Workbook

Sheet CMP Input
A1: MARKET PRICE INPUT — RAJESH POWER SERVICES LTD
A3: Current Market Price — CMP (₹) | B3: 868
A4: Total Shares Outstanding (Cr.) | B4: 1.8007
A5: Market Capitalisation (₹ Cr.) | B5: =B3*B4 -> 1563.0076
A6: Net Debt FY26A (₹ Cr.) [Debt 127 – Cash 65.45] | B6: =Assumptions!B27 -> 61.79
A7: Enterprise Value (₹ Cr.) [MCap + Net Debt] | B7: =B5+B6 -> 1624.7976
A8: EV/EBITDA | B8: 9.19
A9: P/E | B9: 13
A10: P/Sales | B10: 1.11
A12: Change cell B3 to update upside/downside across model automatically.
A13: Colour Key: Blue = Hardcoded input | Green = Linked from Assumptions tab | Yellow = Key output

Sheet Financials
A1: ① INCOME STATEMENT (₹ Cr.)
A2: Particulars | B2: FY23A (Standalone) | C2: FY24A (Standalone) | D2: FY25A (Consolidated) | E2: FY26A (Consolidated) | F2: FY27E | G2: FY28E | H2: FY29E
A3: Revenue from Operations | B3: 207.18 | C3: 284.97 | D3: 1107.43 | E3: 1627.94 | F3: =Assumptions!F5 -> 2279.116 | G3: =Assumptions!G5 -> 3190.7624 | H3: =Assumptions!H5 -> 4467.0674
A4: Other Income | B4: 4 | C4: 10.09 | D4: 7.22 | E4: 5.47 | F4: =Assumptions!F9 -> 5.47 | G4: =Assumptions!G9 -> 5.47 | H4: =Assumptions!H9 -> 5.47
A5: Total Income | B5: =B3+B4 -> 211.18 | C5: =SUM(C3:C4) -> 295.06 | D5: =SUM(D3:D4) -> 1114.65 | E5: =SUM(E3:E4) -> 1633.41 | F5: =F3+F4 -> 2284.586 | G5: =G3+G4 -> 3196.2324 | H5: =H3+H4 -> 4472.5374
A7: Cost of Goods Sold | B7: =173.47-8.9 -> 164.57 | C7: =207.06+0.4 -> 207.46 | D7: =920.04-25.63 -> 894.41 | E7: 1329.5 | F7: =Assumptions!F14 -> 1920.45 | G7: =Assumptions!G14 -> 2688.63 | H7: =Assumptions!H14 -> 3764.082
A8: Employee Benefit Expenses | B8: 21.28 | C8: 28.91 | D8: 47.28 | E8: 59.01 | F8: =Assumptions!F12 -> 82.614 | G8: =Assumptions!G12 -> 115.6596 | H8: =Assumptions!H12 -> 161.92344
A9: Finance Costs | B9: 8.47 | C9: 9.29 | D9: 16.65 | E9: 10.9 | F9: =Assumptions!F19 -> 13.640077 | G9: =Assumptions!G19 -> 17.55414 | H9: =Assumptions!H19 -> 23.033828
A10: Depreciation & Amortisation | B10: 0.94 | C10: 0.7 | D10: 1.21 | E10: 1.14 | F10: =Assumptions!F16 -> 1.596 | G10: =Assumptions!G16 -> 2.2344 | H10: =Assumptions!H16 -> 3.12816
A11: Other Expenses | B11: 7.22 | C11: 14.53 | D11: 32 | E11: 42.25 | F11: =Assumptions!F13 -> 59.15 | G11: =Assumptions!G13 -> 82.81 | H11: =Assumptions!H13 -> 115.934
A12: Total Expenses | B12: =SUM(B7:B11) -> 202.48 | C12: =SUM(C7:C11) -> 260.89 | D12: =SUM(D7:D11) -> 991.55 | E12: =SUM(E7:E11) -> 1442.8 | F12: =SUM(F7:F11) -> 2077.4501 | G12: =SUM(G7:G11) -> 2906.8881 | H12: =SUM(H7:H11) -> 4068.1014
A14: EBITDA (excl. Other Income) | B14: =B3-B7-B8-B11 -> 14.11 | C14: =C3-C7-C8-C11 -> 34.07 | D14: =D3-D7-D8-D11 -> 133.74 | E14: =E3-E7-E8-E11 -> 197.18 | F14: =F3-F7-F8-F11 -> 216.902 | G14: =G3-G7-G8-G11 -> 303.6628 | H14: =H3-H7-H8-H11 -> 425.12792
A15: EBITDA Margin % | B15: =IFERROR(B14/B3,0) -> 0.068105029 | C15: =IFERROR(C14/C3,0) -> 0.11955644 | D15: =IFERROR(D14/D3,0) -> 0.1207661 | E15: =IFERROR(E14/E3,0) -> 0.1211224 | F15: =IFERROR(F14/F3,0) -> 0.095169355 | G15: =IFERROR(G14/G3,0) -> 0.095169355 | H15: =IFERROR(H14/H3,0) -> 0.095169355
A17: EBIT | B17: =B14-B10 -> 13.17 | C17: =C14-C10 -> 33.37 | D17: =D14-D10 -> 132.53 | E17: =E14-E10 -> 196.04 | F17: =F14-F10 -> 215.306 | G17: =G14-G10 -> 301.4284 | H17: =H14-H10 -> 421.99976
A18: PBT (before exceptional) | B18: =B17-B9 -> 4.7 | C18: =C17-C9 -> 24.08 | D18: =D17-D9 -> 115.88 | E18: =E17-E9 -> 185.14 | F18: =F17-F9 -> 201.66592 | G18: =G17-G9 -> 283.87426 | H18: =H17-H9 -> 398.96593
A19: Exceptional Items | B19: 0 | C19: 0 | D19: 0 | E19: 0.64 | F19: 0 | G19: 0 | H19: 0
A20: PBT (after exceptional) | B20: =B18+B19+B4 -> 8.7 | C20: =C18+C19+C4 -> 34.17 | D20: =D18+D19+D4 -> 123.1 | E20: =E18+E19+E4 -> 191.25 | F20: =F18+F19+F4 -> 207.13592 | G20: =G18+G19+G4 -> 289.34426 | H20: =H18+H19+H4 -> 404.43593
A21: Tax | B21: 1.89 | C21: 8.05 | D21: 29.75 | E21: 52.44 | F21: =F20*Assumptions!$B$22 -> 52.136112 | G21: =G20*Assumptions!$B$22 -> 72.82795 | H21: =H20*Assumptions!$B$22 -> 101.79652
A22: Effective Tax Rate % | B22: =IFERROR(B21/B20,0) -> 0.21724138 | C22: =IFERROR(C21/C20,0) -> 0.23558677 | D22: =IFERROR(D21/D20,0) -> 0.24167344 | E22: =IFERROR(E21/E20,0) -> 0.27419608 | F22: =IFERROR(F21/F20,0) -> 0.2517 | G22: =IFERROR(G21/G20,0) -> 0.2517 | H22: =IFERROR(H21/H20,0) -> 0.2517
A24: PAT | B24: =B20-B21 -> 6.81 | C24: =C20-C21 -> 26.12 | D24: =D20-D21 -> 93.35 | E24: =E20-E21 -> 138.81 | F24: =F20-F21 -> 154.99981 | G24: =G20-G21 -> 216.51631 | H24: =H20-H21 -> 302.63941
A25: PAT Margin % | B25: =IFERROR(B24/B3,0) -> 0.032869968 | C25: =IFERROR(C24/C3,0) -> 0.091658771 | D25: =IFERROR(D24/D3,0) -> 0.084294267 | E25: =IFERROR(E24/E3,0) -> 0.08526727 | F25: =IFERROR(F24/F3,0) -> 0.068008742 | G25: =IFERROR(G24/G3,0) -> 0.067857234 | H25: =IFERROR(H24/H3,0) -> 0.067749014
A26: EPS (₹ per share) | B26: 4.4 | C26: 17.1 | D26: 57.74 | E26: 79.19 | F26: =F24/Assumptions!$B$25 -> 86.077532 | G26: =G24/Assumptions!$B$25 -> 120.24008 | H26: =H24/Assumptions!$B$25 -> 168.06764
A28: ② BALANCE SHEET (₹ Cr.)
A29: Particulars | B29: FY23A (Standalone) | C29: FY24A (Standalone) | D29: FY25A (Consolidated) | E29: FY26A (Consolidated) | F29: FY27E | G29: FY28E | H29: FY29E
A30: ASSETS
A31: Property Plant & Equipment | B31: 19.01 | C31: 19.83 | D31: 18.3 | E31: 19.26 | F31: =E31+Assumptions!F17-Assumptions!F16 -> 20.626851 | G31: =F31+Assumptions!G17-Assumptions!G16 -> 22.540442 | H31: =G31+Assumptions!H17-Assumptions!H16 -> 25.219469
A32: Other Non-Current Assets | B32: 1.38 | C32: 6.35 | D32: 188.81 | E32: 343.54 | F32: =E32+Assumptions!F43 -> 343.54 | G32: =F32+Assumptions!G43 -> 343.54 | H32: =G32+Assumptions!H43 -> 343.54
A33: Total Non-Current Assets | B33: =SUM(B31:B32) -> 20.39 | C33: =SUM(C31:C32) -> 26.18 | D33: =SUM(D31:D32) -> 207.11 | E33: =SUM(E31:E32) -> 362.8 | F33: =SUM(F31:F32) -> 364.16685 | G33: =SUM(G31:G32) -> 366.08044 | H33: =SUM(H31:H32) -> 368.75947
A35: Inventories | B35: 36.86 | C35: 36.45 | D35: 62.85 | E35: 124.95 | F35: =Assumptions!F14*Assumptions!$B$32/365 -> 147.32219 | G35: =Assumptions!G14*Assumptions!$B$32/365 -> 206.25107 | H35: =Assumptions!H14*Assumptions!$B$32/365 -> 288.7515
A36: Trade Receivables | B36: 76.26 | C36: 114.04 | D36: 181.71 | E36: 348.77 | F36: =Financials!F3*Assumptions!$B$31/365 -> 374.64921 | G36: =Financials!G3*Assumptions!$B$31/365 -> 524.50889 | H36: =Financials!H3*Assumptions!$B$31/365 -> 734.31244
A37: Cash & Bank Balances | B37: 0.24 | C37: 0.17 | D37: 49.04 | E37: 65.45 | F37: =Assumptions!F37 -> 151.81705 | G37: =Assumptions!G37 -> 402.91862 | H37: =Assumptions!H37 -> 747.34387
A38: Other Current Assets | B38: 60.27 | C38: 63.55 | D38: 56.26 | E38: 40.46 | F38: =Financials!F3*0.025 -> 56.9779 | G38: =Financials!G3*0.025 -> 79.76906 | H38: =Financials!H3*0.025 -> 111.67668
A39: Total Current Assets | B39: =SUM(B35:B38) -> 173.63 | C39: =SUM(C35:C38) -> 214.21 | D39: =SUM(D35:D38) -> 349.86 | E39: =SUM(E35:E38) -> 579.63 | F39: =SUM(F35:F38) -> 730.76635 | G39: =SUM(G35:G38) -> 1213.4476 | H39: =SUM(H35:H38) -> 1882.0845
A40: TOTAL ASSETS | B40: =B33+B39 -> 194.02 | C40: =C33+C39 -> 240.39 | D40: =D33+D39 -> 556.97 | E40: =E33+E39 -> 942.43 | F40: =F33+F39 -> 1094.9332 | G40: =G33+G39 -> 1579.5281 | H40: =H33+H39 -> 2250.844
A42: EQUITY & LIABILITIES
A43: Equity Share Capital | B43: 15.22 | C43: 15.22 | D43: 18.01 | E43: 18.01 | F43: 18.01 | G43: 18.01 | H43: 18.01
A44: Other Equity | B44: 43.45 | C44: 69.08 | D44: 246.87 | E44: 388.16 | F44: =E44+Financials!F24-Assumptions!$B$23 -> 541.35981 | G44: =F44+Financials!G24-Assumptions!$B$23 -> 756.07612 | H44: =G44+Financials!H24-Assumptions!$B$23 -> 1056.9155
A45: Total Equity (Net Worth) | B45: =SUM(B43:B44) -> 58.67 | C45: =SUM(C43:C44) -> 84.3 | D45: =SUM(D43:D44) -> 264.88 | E45: =SUM(E43:E44) -> 406.17 | F45: =SUM(F43:F44) -> 559.36981 | G45: =SUM(G43:G44) -> 774.08612 | H45: =SUM(H43:H44) -> 1074.9255
A47: Long-Term Borrowings | B47: 39.2 | C47: 47.07 | D47: 48.96 | E47: 45.65 | F47: 45 | G47: 45 | H47: 45
A48: Other Non-Current Liabilities | B48: 5.15 | C48: 6.6 | D48: 8.01 | E48: 9.82 | F48: =E48*1.05 -> 10.311 | G48: =F48*1.05 -> 10.82655 | H48: =G48*1.05 -> 11.367878
...

Sheet Assumptions
A1: MODEL ASSUMPTIONS — RAJESH POWER SERVICES LTD (All values in ₹ Cr.)
A2: Assumption / Driver | B2: FY26A Base (Input) | C2: FY23A | D2: FY24A | E2: FY25A | F2: FY27E | G2: FY28E | H2: FY29E
A3: A. REVENUE
A4: Revenue Growth Rate (Base: 40% CAGR | Mgmt guidance: 40% CAGR over 4-5 yrs) | B4: =Financials!E3/Financials!D3-1 -> 0.47001616 | D4: =Financials!C3/Financials!B3-1 -> 0.37547061 | E4: =Financials!D3/Financials!C3-1 -> 2.8861284 | F4: 0.4 | G4: 0.4 | H4: 0.4
A5: Revenue from Operations (₹ Cr.) | B5: =Financials!E3 -> 1627.94 | C5: =Financials!B3 -> 207.18 | D5: =Financials!C3 -> 284.97 | E5: =Financials!D3 -> 1107.43 | F5: =B5*(1+F4) -> 2279.116 | G5: =F5*(1+G4) -> 3190.7624 | H5: =G5*(1+H4) -> 4467.0674
A6: — BESS Revenue Ramp (10-15% of total revenue by FY29)
A7: BESS Revenue (₹ Cr.) — 65MW GUVNL project + pipeline | F7: =F8*F5 -> 182.32928 | G7: =G8*G5 -> 319.07624 | H7: =H8*H5 -> 670.0601 | I7: FY27: nil (construction). FY28: ₹7.37 Cr (65MW × 50% ramp, H2 commissioning). FY29: ₹25 Cr (full yr + pipeline BESS). ~11% of FY29E revenue.
A8: BESS as % of Total Revenue (%) | F8: 0.08 | G8: 0.1 | H8: 0.15 | I8: ramp up in revenue in next 3y
A9: Other Income (₹ Cr.) — JV dividend + interest (flat) | B9: =Financials!E4 -> 5.47 | C9: =Financials!B4 -> 4 | D9: =Financials!C4 -> 10.09 | E9: =Financials!D4 -> 7.22 | F9: =$B$9 -> 5.47 | G9: =$B$9 -> 5.47 | H9: =$B$9 -> 5.47 | I9: Flat per management — no growth guidance on JV. JV income separately in row 24.
A10: B. MARGIN ASSUMPTIONS
A11: EBITDA Margin % (Base=12.0% | Bear=10.0% | Bull=13.0% — set in DCF tab) | B11: =Financials!E15 -> 0.1211224 | C11: =Financials!B15 -> 0.068105029 | D11: =Financials!C15 -> 0.11955644 | E11: =Financials!D15 -> 0.1207661 | F11: =$B$11 -> 0.1211224 | G11: =$B$11 -> 0.1211224 | H11: =$B$11 -> 0.1211224 | I11: EBITDA Margin to stay at FY26 level of 12%
A12: Employee Expenses (₹ Cr.) [Rev × 3.6% — FY26: 59.01/1627.94] | B12: =Financials!E8/Financials!E3 -> 0.036248265 | C12: =Financials!B8 -> 21.28 | D12: =Financials!C8 -> 28.91 | E12: =Financials!D8 -> 47.28 | F12: =F5*$B$12 -> 82.614 | G12: =G5*$B$12 -> 115.6596 | H12: =H5*$B$12 -> 161.92344 | I12: Employee expense as a % of operating revenue
A13: Other Expenses (₹ Cr.) [Rev × 2.6% — FY26: 42.27/1627.94] | B13: =Financials!E11/Financials!E3 -> 0.025953045 | C13: =Financials!B11 -> 7.22 | D13: =Financials!C11 -> 14.53 | E13: =Financials!D11 -> 32 | F13: =F5*$B$13 -> 59.15 | G13: =G5*$B$13 -> 82.81 | H13: =H5*$B$13 -> 115.934 | I13: Other expense as a % of operating revenue
A14: Cost of Goods Sold (₹ Cr.) [Rev×(1−EBITDA%−Emp%) ] | B14: =Financials!E7 -> 1329.5 | C14: =Financials!B7 -> 164.57 | D14: =Financials!C7 -> 207.46 | E14: =Financials!D7 -> 894.41 | F14: =F5*(1-$B$11-$B$12) -> 1920.45 | G14: =G5*(1-$B$11-$B$12) -> 2688.63 | H14: =H5*(1-$B$11-$B$12) -> 3764.082
A15: C. DEPRECIATION, AMORTISATION & CAPEX
A16: D&A (₹ Cr.) [Revenue × 0.07% — FY26: 1.14 Cr; held constant as % of revenue] | B16: =Financials!E10/Financials!E3 -> 0.00070027151 | C16: =Financials!B10 -> 0.94 | D16: =Financials!C10 -> 0.7 | E16: =Financials!D10 -> 1.21 | F16: =F5*$B$16 -> 1.596 | G16: =G5*$B$16 -> 2.2344 | H16: =H5*$B$16 -> 3.12816 | I16: Depreciation as a % of revenue
A17: Maintenance Capex (₹ Cr.) [Revenue × 0.13% — FY26: 2.14 Cr; asset-light EPC model] | B17: 2.14 | C17: 1.2 | D17: 1.5 | E17: 2.1 | F17: =F5*0.0013 -> 2.9628508 | G17: =G5*0.0013 -> 4.1479911 | H17: =H5*0.0013 -> 5.8071876 | I17: Maintenance capex as a % of revenue
A18: D. FINANCE COST
A19: Finance Costs (₹ Cr.) [(STB + LTB 45) × 8.5% interest rate] | B19: =Financials!E9/(Financials!E47+Financials!E51) -> 0.085664885 | C19: =Financials!B9 -> 8.47 | D19: =Financials!C9 -> 9.29 | E19: =Financials!D9 -> 16.65 | F19: =(F20+45)*$B$19 -> 13.640077 | G19: =(G20+45)*$B$19 -> 17.55414 | H19: =(H20+45)*$B$19 -> 23.033828
A20: Short-Term Borrowings (₹ Cr.) — grows with WC funding needs | B20: =Financials!E51/Financials!E3 -> 0.050118555 | C20: =Financials!B51 -> 15.94 | D20: =Financials!C51 -> 24.84 | E20: =Financials!D51 -> 28.9 | F20: =$B$20*F5 -> 114.226 | G20: =$B$20*G5 -> 159.9164 | H20: =$B$20*H5 -> 223.88296 | I20: STB as % of revenue
A21: Incremental Borrowings (net, ₹ Cr.) — change in STB | F21: =F20-B20 -> 114.17588 | G21: =G20-F20 -> 45.6904 | H21: =H20-G20 -> 63.96656
A22: Effective Tax Rate [Base rate 25.17% — standard corporate rate] | B22: 0.2517 | F22: =$B$22 -> 0.2517 | G22: =$B$22 -> 0.2517 | H22: =$B$22 -> 0.2517
A23: Dividend Paid (₹ Cr.) — ₹1/share × 1.8007 Cr shares | B23: 1.8 | F23: 1.8 | G23: 1.8 | H23: 1.8
A24: JV / Associate Income (₹ Cr.) — flat, no growth guidance | B24: 5.69 | F24: =$B$24 -> 5.69 | G24: =$B$24 -> 5.69 | H24: =$B$24 -> 5.69
A25: Shares Outstanding (Cr.) | B25: 1.8007
A26: F. WORKING CAPITAL DAYS (Peer-Benchmarked — see Comparables tab)
A27: Net Debt | B27: =(Financials!E47+Financials!E51)-Financials!E37 -> 61.79
A28: G. WORKING CAPITAL DAYS (Peer-Benchmarked — see Comparables tab)
A29: Debtor Days (receivable collection period) | B29: 60 | C29: Assumption: 50d. RPSL FY26 adj. ~45d | KEC 92d | Skipper 67d | Techno 61d. Taking 50d (conservative, above RPSL actual, below peers).
A30: Payable Days (creditor payment period) | B30: 85 | C30: Assumption: 85d. RPSL FY26 ~90d | KEC 86d | Skipper 72d | Techno 44d. Normalising to 85d, in line with KEC peer (same scale EPC).
A31: Debtor Days (receivable collection period — assumption) | B31: 60 | C31: 50d: RPSL FY26 adj ~45d | KEC 92d | Skipper 67d | Techno 61d → conservative mid-point
A32: Inventory Days (stock holding period — assumption) | B32: 28 | C32: 28d: RPSL FY26 actual 28d | KEC 41d | Techno 25d → retaining actual (project-specific procurement)
A33: Payable Days (creditor payment period — assumption) | B33: 85 | C33: 85d: RPSL FY26 ~90d | KEC 86d | Skipper 72d → normalised to 85d (KEC-peer comparable)
A34: G. CHANGE IN WORKING CAPITAL (₹ Cr.)
A35: Δ Working Capital (₹ Cr.) [outflow negative — referenced by CF Statement] | B35: =Financials!C63 -> -216.16 | F35: =-((F5*$B$31/365+F14*$B$32/365-F14*$B$33/365)-(B5*$B$31/365+B14*$B$32/365-B14*$B$33/365)) -> -14.757288 | G35: =-((G5*$B$31/365+G14*$B$32/365-G14*$B$33/365)-(F5*$B$31/365+F14*$B$32/365-F14*$B$33/365)) -> -29.897326 | H35: =-((H5*$B$31/365+H14*$B$32/365-H14*$B$33/365)-(G5*$B$31/365+G14*$B$32/365-G14*$B$33/365)) -> -41.856256
A36: H. CLOSING CASH (Linked from CF Statement)
A37: Closing Cash & Bank (₹ Cr.) | B37: =Financials!C81 -> 1.18 | F37: =Financials!D81 -> 151.81705 | G37: =Financials!E81 -> 402.91862 | H37: =Financials!F81 -> 747.34387
A38: I. BESS PROJECT ASSUMPTIONS — 65 MW / 130 MWh (GUVNL Phase VII PSDF)
A39: Total Project Cost (₹ Cr.) [130 MWh × ₹3.35 Cr/MWh] | B39: 435.5
A40: Project Finance — Debt 70% (₹ Cr.) [Off-balance-sheet SPV debt] | B40: 304.85
...

Sheet DCF & Valuation
A1: RAJESH POWER SERVICES LTD — DCF & VALUATION MODEL (₹ Cr. | All forecasts are Base Case unless stated)
B2: Base Input | C2: FY23A | D2: FY24A | E2: FY25A | F2: FY27E | G2: FY28E | H2: FY29E
A3: ① REVENUE SCENARIOS (₹ Cr.)
A4: Bear Case — Revenue Growth Rate | D4: =Financials!C5/Financials!B5-1 -> 0.3971967 | E4: =Financials!D5/Financials!C5-1 -> 2.7777062 | F4: 0.25 | G4: 0.25 | H4: 0.25
A5: Base Case — Revenue Growth Rate | D5: =D4 -> 0.3971967 | E5: =E4 -> 2.7777062 | F5: 0.4 | G5: 0.4 | H5: 0.4
A6: Bull Case — Revenue Growth Rate | D6: =D5 -> 0.3971967 | E6: =E5 -> 2.7777062 | F6: 0.55 | G6: 0.55 | H6: 0.55
A7: Bear Case — Revenue (₹ Cr.) | C7: =Financials!B5 -> 211.18 | D7: =Financials!C5 -> 295.06 | E7: =Financials!D5 -> 1114.65 | F7: =1627.94*(1+F4) -> 2034.925 | G7: =F7*(1+G4) -> 2543.6562 | H7: =G7*(1+H4) -> 3179.5703
A8: Base Case — Revenue (₹ Cr.) | C8: =C7 -> 211.18 | D8: =D7 -> 295.06 | E8: =E7 -> 1114.65 | F8: =1627.94*(1+F5) -> 2279.116 | G8: =F8*(1+G5) -> 3190.7624 | H8: =G8*(1+H5) -> 4467.0674
A9: Bull Case — Revenue (₹ Cr.) | C9: =C8 -> 211.18 | D9: =D8 -> 295.06 | E9: =E8 -> 1114.65 | F9: =1627.94*(1+F6) -> 2523.307 | G9: =F9*(1+G6) -> 3911.1259 | H9: =G9*(1+H6) -> 6062.2451
A11: ② EBITDA BRIDGE — Margin × Revenue (₹ Cr.)
A12: Bear Case — EBITDA Margin % | B12: 0.1 | C12: =Financials!B15 -> 0.068105029 | D12: =Financials!C15 -> 0.11955644 | E12: =Financials!D15 -> 0.1207661 | F12: =B12 -> 0.1 | G12: =B12 -> 0.1 | H12: =B12 -> 0.1
A13: Bear Case — EBITDA (₹ Cr.) | C13: =C7*C12 -> 14.38242 | D13: =D7*D12 -> 35.276325 | E13: =E7*E12 -> 134.61193 | F13: =F7*F12 -> 203.4925 | G13: =G7*G12 -> 254.36563 | H13: =H7*H12 -> 317.95703
A14: Base Case — EBITDA Margin % | B14: 0.12 | C14: =C12 -> 0.068105029 | D14: =D12 -> 0.11955644 | E14: =E12 -> 0.1207661 | F14: =B14 -> 0.12 | G14: =B14 -> 0.12 | H14: =B14 -> 0.12
A15: Base Case — EBITDA (₹ Cr.) | C15: =C13 -> 14.38242 | D15: =D13 -> 35.276325 | E15: =E13 -> 134.61193 | F15: =F8*F14 -> 273.49392 | G15: =G8*G14 -> 382.89149 | H15: =H8*H14 -> 536.04808
A16: Bull Case — EBITDA Margin % | B16: 0.13 | C16: =C14 -> 0.068105029 | D16: =D14 -> 0.11955644 | E16: =E14 -> 0.1207661 | F16: =B16 -> 0.13 | G16: =B16 -> 0.13 | H16: =B16 -> 0.13
A17: Bull Case — EBITDA (₹ Cr.) | C17: =C15 -> 14.38242 | D17: =D15 -> 35.276325 | E17: =E15 -> 134.61193 | F17: =F9*F16 -> 328.02991 | G17: =G9*G16 -> 508.44636 | H17: =H9*H16 -> 788.09186
A19: ③ FCFF WATERFALL — Base Case (₹ Cr.)
A20: EBITDA | F20: =F15 -> 273.49392 | G20: =G15 -> 382.89149 | H20: =H15 -> 536.04808
A21: (-) Depreciation & Amort. | F21: =Assumptions!F16 -> 1.596 | G21: =Assumptions!G16 -> 2.2344 | H21: =Assumptions!H16 -> 3.12816
A22: EBIT | F22: =F20-F21 -> 271.89792 | G22: =G20-G21 -> 380.65709 | H22: =H20-H21 -> 532.91992
A23: (-) Tax on EBIT @ 25.17% | F23: =F22*Assumptions!$B$22 -> 68.436706 | G23: =G22*Assumptions!$B$22 -> 95.811389 | H23: =H22*Assumptions!$B$22 -> 134.13594
A24: NOPAT | F24: =F22-F23 -> 203.46121 | G24: =G22-G23 -> 284.8457 | H24: =H22-H23 -> 398.78398
A25: (+) D&A add-back | F25: =Assumptions!F16 -> 1.596 | G25: =Assumptions!G16 -> 2.2344 | H25: =Assumptions!H16 -> 3.12816
A26: (-) Maintenance Capex | F26: =-Assumptions!F17 -> -2.9628508 | G26: =-Assumptions!G17 -> -4.1479911 | H26: =-Assumptions!H17 -> -5.8071876
A27: (-) Δ Net Working Capital | F27: =Assumptions!F35 -> -14.757288 | G27: =Assumptions!G35 -> -29.897326 | H27: =Assumptions!H35 -> -41.856256
A28: FCFF | F28: =F24+F25+F26+F27 -> 187.33708 | G28: =G24+G25+G26+G27 -> 253.03478 | H28: =H24+H25+H26+H27 -> 354.24869
A30: ④ WACC SUMMARY
A31: Risk-free Rate (10Y G-Sec) | B31: 0.0698
A32: Equity Risk Premium (India ERP) | B32: 0.0708 | C32: Jan'26 Damodaran Estimates
A33: Beta (Levered, T&D EPC) | B33: 1.5
A34: Cost of Equity [Rf + β × ERP] | B34: =B31+(B33*B32) -> 0.176
A35: Cost of Debt (pre-tax 8.5%) | B35: =Assumptions!B19 -> 0.085664885
A36: Cost of Debt (after tax) | B36: =B35*(1-Assumptions!$B$22) -> 0.064103034 | D36: Total Equity | E36: 391 | F36: =E36/$E$38 -> 0.75482625
A37: Weight of Equity | B37: =F36 -> 0.75482625 | D37: Total Debt | E37: 127 | F37: =E37/$E$38 -> 0.24517375
A38: Weight of Debt | B38: =1-B37 -> 0.24517375 | D38: Total | E38: =SUM(E36:E37) -> 518
A39: WACC | B39: =(B34*B37)+(B36*B38) -> 0.1485658
A40: Terminal Growth Rate | B40: 0.045
A42: ⑤ VALUATION TABLE — Bear / Base / Bull (₹ Cr. and ₹ per share)
A43: Metric | B43: Bear Case (₹ Cr.) | C43: Bear (₹/sh) | D43: Base Case (₹ Cr.) | E43: Base (₹/sh) | F43: Bull Case (₹ Cr.) | G43: Bull (₹/sh)
A44: FY29E EBITDA (₹ Cr.) | B44: =H13 -> 317.95703 | D44: =H15 -> 536.04808 | F44: =H17 -> 788.09186
...

Sheet Comparables
A1: COMPARABLE COMPANIES — India T&D EPC Sector (FY26 Actuals | Source: BSE / NSE / Company Filings)
A2: Company | B2: MCap (₹ Cr.) | C2: EV | D2: TTM Revenue (₹ Cr.) | E2: EBITDA (₹ Cr.) | F2: EBITDA Margin | G2: PAT (₹ Cr.) | H2: PAT Margin | I2: EV/ EBITDA | J2: P/E (x) | K2: P/Sales (x) | L2: RoCE (%)
A3: KEC International | B3: 15209 | C3: 20105 | D3: 23988 | E3: 1749 | F3: =E3/D3 -> 0.072911456 | G3: 681 | H3: =G3/D3 -> 0.028389195 | I3: =C3/E3 -> 11.49514 | J3: =B3/G3 -> 22.333333 | K3: =B3/D3 -> 0.63402535 | L3: 0.18
A4: Skipper Ltd | B4: 5535 | C4: 6280 | D4: 5553 | E4: 573 | F4: =E4/D4 -> 0.10318747 | G4: 207 | H4: =G4/D4 -> 0.037277147 | I4: =C4/E4 -> 10.95986 | J4: =B4/G4 -> 26.73913 | K4: =B4/D4 -> 0.99675851 | L4: 0.266
A5: Techno Electric & Engg | B5: 14708 | C5: 14628 | D5: 3057 | E5: 456 | F5: =E5/D5 -> 0.14916585 | G5: 494 | H5: =G5/D5 -> 0.16159634 | I5: =C5/E5 -> 32.078947 | J5: =B5/G5 -> 29.773279 | K5: =B5/D5 -> 4.8112529 | L5: 0.165
A6: Viviana Power | B6: 827 | C6: 896 | D6: 343 | E6: 50 | F6: =E6/D6 -> 0.14577259 | G6: 29 | H6: =G6/D6 -> 0.084548105 | I6: =C6/E6 -> 17.92 | J6: =B6/G6 -> 28.517241 | K6: =B6/D6 -> 2.4110787 | L6: 0.429
A7: RPSL (FY26 Actual) | B7: 1801 | C7: 1863 | D7: 1628 | E7: 197 | F7: =E7/D7 -> 0.12100737 | G7: 138 | H7: =G7/D7 -> 0.084766585 | I7: =C7/E7 -> 9.4568528 | J7: =B7/G7 -> 13.050725 | K7: =B7/D7 -> 1.1062654 | L7: 0.486
A9: Peer Average (excl. RPSL) | B9: =AVERAGE(B3:B6) -> 9069.75 | C9: =AVERAGE(C3:C6) -> 10477.25 | D9: =AVERAGE(D3:D6) -> 8235.25 | E9: =AVERAGE(E3:E6) -> 707 | F9: =AVERAGE(F3:F6) -> 0.11775934 | G9: =AVERAGE(G3:G6) -> 352.75 | H9: =AVERAGE(H3:H6) -> 0.077952696 | I9: =AVERAGE(I3:I6) -> 18.113487 | ... K9: =AVERAGE(K3:K6) -> 2.2132789 | L9: 0.26
A11: DEBTOR DAYS — FY22 to FY26 (Peer Benchmark)
A12: Company | B12: FY22 | C12: FY23 | D12: FY24 | E12: FY25 | F12: FY26 | G12: 5Y Avg
A13: KEC International | B13: 136 | C13: 90 | D13: 76 | E13: 84 | F13: - | G13: =AVERAGE(B13:F13) -> 96.5
A14: Skipper Ltd | B14: 93 | C14: 66 | D14: 85 | E14: 55 | F14: - | G14: =AVERAGE(B14:F14) -> 74.75
A15: Techno Electric & Engg | B15: 213 | C15: 282 | D15: 180 | E15: 108 | F15: - | G15: =AVERAGE(B15:F15) -> 195.75
A16: Viviana Power | C16: 204 | D16: 153 | E16: 207 | F16: - | G16: =AVERAGE(B16:F16) -> 188
A17: RPSL (FY26 adj.) | B17: 141 | C17: 103 | D17: 94 | E17: 62 | F17: 78
A19: INVENTORY DAYS — FY22 to FY26 (Peer Benchmark)
A20: Company | B20: FY22 | C20: FY23 | D20: FY24 | E20: FY25 | F20: FY26 | G20: 5Y Avg
A21: KEC International | B21: 65 | C21: 59 | D21: 53 | E21: 41 | F21: - | G21: =AVERAGE(B21:F21) -> 54.5
A22: Skipper Ltd | B22: 251 | C22: 263 | D22: 263 | E22: 152 | F22: - | G22: =AVERAGE(B22:F22) -> 232.25
A23: Techno Electric & Engg | B23: 13 | C23: 59 | D23: 8 | E23: 0 | F23: - | G23: =AVERAGE(B23:F23) -> 20
A24: Viviana Power | B24: - | C24: - | D24: 44 | E24: 29 | F24: - | G24: =AVERAGE(B24:F24) -> 36.5
A25: RPSL (FY26 actual) | B25: 95 | C25: 82 | D25: 64 | E25: 26 | F25: 34
A27: PAYABLE DAYS — FY22 to FY26 (Peer Benchmark)
A28: Company | B28: FY22 | C28: FY23 | D28: FY24 | E28: FY25 | F28: FY26 | G28: 5Y Avg
A29: KEC International | B29: 420 | C29: 433 | D29: 401 | E29: 380 | F29: - | G29: =AVERAGE(B29:F29) -> 408.5
A30: Skipper Ltd | B30: 200 | C30: 169 | D30: 267 | E30: 155 | F30: - | G30: =AVERAGE(B30:F30) -> 197.75
A31: Techno Electric & Engg | B31: 205 | C31: 303 | D31: 173 | E31: - | F31: - | G31: =AVERAGE(B31:F31) -> 227
A32: Viviana Power | B32: - | C32: - | D32: 33 | E32: 236 | F32: - | G32: =AVERAGE(B32:F32) -> 134.5
A33: RPSL (FY26 actual) | B33: 116 | C33: 76 | D33: 55 | E33: 50 | F33: 90
