Workbook

Sheet DCF & Valuation
A1: CMP & Company Input
A2: Input Parameter | B2: Value | C2: Notes / Source
A3: Company Name | B3: Transrail Lighting
A4: NSE/BSE Ticker | B4: TRANSRAILL
A5: Face Value | B5: 2
A6: Equity Capital | B6: 26.85
A7: Shares Outstanding (Cr.) | B7: =B6/B5 -> 13.425 | C7: Equity capital/FV
A8: CMP (₹) | B8: 481.7 | C8: Live or last traded price
A9: Market Cap (₹ Cr.) | B9: =B8*B7 -> 6466.8225
A10: Total Debt (₹ Cr.) | B10: 678 | C10: Long term + Short term
A11: Cash & Equivalents (₹ Cr.) | B11: 763 | C11: Latest balance sheet
A12: Net Debt (₹ Cr.) | B12: =B10-B11 -> -85 | C12: Total debt - Cash
A13: Enterprise Value @ CMP (₹ Cr.) | B13: =B9+B12 -> 6381.8225 | C13: EV = Market Cap + Net Debt
A16: Assumptions (Revenue growth & EBITDA Margins)
A17: Assumption | B17: Base Input (FY26) | C17: FY27E | D17: FY28E | E17: FY29E
A18: Revenue Assumptions (₹ Cr.)
A19: FY26 Revenue (₹ Cr.) | B19: 6880
A20: Bear Case - Revenue Growth % | C20: 0.18 | D20: 0.16 | E20: 0.14
A21: Base Case - Revenue Growth % | C21: 0.2 | D21: 0.18 | E21: 0.16
A22: Bull Case - Revenue Growth % | C22: 0.22 | D22: 0.2 | E22: 0.18
A23: EBITDA Margins Assumptions
A24: Bear Case — EBITDA Margin % | C24: 0.105 | D24: 0.105 | E24: 0.105
A25: Base Case — EBITDA Margin % | C25: 0.115 | D25: 0.116 | E25: 0.117
A26: Bull Case — EBITDA Margin % | C26: 0.125 | D26: 0.125 | E26: 0.125
A27: FCFF / Bridge Assumptions
A28: Tax Rate % | B28: =Assumptions!B17 -> 0.2517
A29: D&A (₹ Cr.) - FY27E | B29: 78.6
A30: D&A (₹ Cr.) - FY28E | B30: 107.1
A31: D&A (₹ Cr.) - FY29E | B31: 120.9
A32: Capex (₹ Cr.) - FY27E | B32: 185
A33: Capex (₹ Cr.) - FY28E | B33: 209
A34: Capex (₹ Cr.) - FY29E | B34: 192.8
A35: Δ NWC (₹ Cr.) - FY27E | B35: 186.5
A36: Δ NWC (₹ Cr.) - FY28E | B36: 337.2
A37: Δ NWC (₹ Cr.) - FY29E | B37: 471.3
A38: WACC Assumptions
A39: Risk-free Rate (IN10Y yield-Bond default spread) | B39: =Assumptions!B4 -> 0.0565 | C39: Changes made in "Assumptions" sheet will get reflected here
A40: Equity Risk Premium % | B40: =Assumptions!B13 -> 0.12266803
A41: Beta (Levered) | B41: =Assumptions!B18 -> 0.86800959
A42: Cost of Debt (pre-tax %) | B42: =Assumptions!B22 -> 0.10516553
...

Sheet Assumptions
A1: Particulars
A2: 10y Gov Bond | B2: 0.074
A3: Bond default spread | B3: 0.0175
A4: Rf | B4: =B2-B3 -> 0.0565
A6: Mature market ERP | B6: 0.0442 | D6: Revenue sources (%) | G6: Middle East Countries | H6: ERP | J6: North Africa Countries
A7: India country risk premium | B7: =B8*(B9/B10) -> 0.094694269 | D7: Domestic | E7: 0.45 | G7: Abu Dhabi | H7: 0.0481 | J7: Egypt | K7: 0.1348
A8: Default spread | B8: =B3 -> 0.0175 | D8: International | E8: =1-E7 -> 0.55 | G8: Bahrain | H8: 0.1101 | J8: Morocco | K8: 0.073
A9: SD Equity | B9: 0.16233303 | G9: Iraq | H9: 0.1348 | J9: Tunisia | K9: 0.1348
A10: SD Bond | B10: 0.03 | D10: Revenue weighted ERP | G10: Israel | H10: 0.0618 | J10: Algeria | K10: 0.0977
A11: India ERP | B11: =B6+B7 -> 0.13889427 | D11: India ERP | E11: =B11*E7 -> 0.062502421 | G11: Jordan | H11: 0.0865 | J11: Iran | K11: 0.1534
A12: MENA EPR | B12: =K15 -> 0.10939201 | D12: MENA EPR | E12: =B12*E8 -> 0.060165605 | G12: Kuwait | H12: 0.0507 | J12: Libya | K12: 0.0977
A13: Total ERP | B13: =SUM(E11:E12) -> 0.12266803 | G13: Lebanon | H13: 0.314 | J13: Yemen | K13: 0.1905 | L13: =AVERAGE(K7:K13) -> 0.12598571
G14: Oman | H14: 0.069181326
A15: Unlevered beta (Sector) | B15: ='Beta calculation'!U4 -> 0.70887438 | G15: Qatar | H15: 0.0481 | J15: MENA Region ERP | K15: =AVERAGE(L13,I17) -> 0.10939201
A16: Target D/E | B16: 0.3 | G16: Saudi Arabia | H16: 0.0494
A17: Tax rate | B17: 0.2517 | G17: United Arab Emirates | H17: 0.0481 | I17: =AVERAGE(H7:H17) -> 0.092798302
A18: Re-levered beta | B18: =B15*(1+(1-B17)*B16) -> 0.86800959
A20: Cost of equity | B20: =B4+(B18*B13) -> 0.16297702
A22: Pretax cost of debt | B22: =G25 -> 0.10516553 | D22: Facility | E22: FY25 Amount | F22: Rate | G22: Weighted cost
A23: Tax rate | B23: 0.2517 | D23: LT Term Loans | E23: 136.86 | F23: 0.085 | G23: =F23*(E23/$E$25) -> 0.016437201
A24: Post tax cost of debt | B24: =B22*(1-B23) -> 0.078695366 | D24: ST CC/WCDL | E24: 570.87 | F24: 0.11 | G24: =F24*(E24/$E$25) -> 0.088728329
E25: =SUM(E23:E24) -> 707.73 | G25: =SUM(G23:G24) -> 0.10516553
A26: Total Debt (FY26E) | B26: 678 | C26: =B26/SUM($B$26:$B$27) -> 0.22913146
A27: Total Equity (FY26E) | B27: 2281 | C27: =B27/SUM($B$26:$B$27) -> 0.77086854
A29: WACC | B29: =(B24*C26)+(B20*C27) -> 0.14366544
A31: Terminal growth rate % | B31: 0.045
A33: EV/EBITDA Exit multiple | B33: 9

Sheet Beta calculation
A1: Date | B1: CNX500 | C1: % return | D1: KEC International | E1: % return | H1: Kalpataru Projects | I1: % return | L1: Skipper | M1: % return | P1: Bajaj electricals | Q1: % return
A2: 44197 | B2: 11574.85 | D2: 354.59453 | H2: 293.67428 | L2: 65.470728 | P2: 536.25852
A3: 44200 | B3: 11691.8 | C3: =B3/B2-1 -> 0.01010382 | D3: 359.12289 | E3: =D3/D2-1 -> 0.012770533 | F3: Levered beta | G3: =SLOPE(E3:E1435,$C$3:$C$1435) -> 1.0334993 | H3: 296.21312 | I3: =H3/H2-1 -> 0.0086450799 | J3: Levered beta | K3: =SLOPE(I3:I1435,$C$3:$C$1435) -> 0.92791843 | L3: 66.248978 | M3: =L3/L2-1 -> 0.011886993 | N3: Levered beta | O3: =SLOPE(M3:M1435,$C$3:$C$1435) -> 1.5910694 | P3: 537.88278 | Q3: =P3/P2-1 -> 0.0030288627 | R3: Levered beta | S3: =SLOPE(Q3:Q1435,$C$3:$C$1435) -> 0.85009433 | U3: Total weighted avg unlevered beta
A4: 44201 | B4: 11767 | C4: =B4/B3-1 -> 0.006431875 | D4: 361.45856 | E4: =D4/D3-1 -> 0.006503796 | F4: debt to equity | G4: 0.87 | H4: 293.16649 | I4: =H4/H3-1 -> -0.010285242 | J4: debt to equity | K4: 0.46 | L4: 65.227523 | M4: =L4/L3-1 -> -0.015418428 | N4: debt to equity | O4: 0.63 | P4: 545.6966 | Q4: =P4/P3-1 -> 0.014527005 | R4: debt to equity | S4: 0.1 | U4: =(G6*G8)+(K6*K8)+(O6*O8)+(S6*S8) -> 0.70887438
A5: 44202 | B5: 11737.9 | C5: =B5/B4-1 -> -0.0024729846 | D5: 353.35517 | E5: =D5/D4-1 -> -0.022418568 | F5: Tax rate | G5: 0.2517 | H5: 301.93702 | I5: =H5/H4-1 -> 0.02991655 | J5: Tax rate | K5: 0.2517 | L5: 63.379165 | M5: =L5/L4-1 -> -0.028337074 | N5: Tax rate | O5: 0.2517 | P5: 552.72029 | Q5: =P5/P4-1 -> 0.012871048 | R5: Tax rate | S5: 0.2517
A6: 44203 | B6: 11766.1 | C6: =B6/B5-1 -> 0.0024024074 | D6: 349.25583 | E6: =D6/D5-1 -> -0.011601187 | F6: unlevered beta | G6: =G3/(1+(1-G5)*G4) -> 0.62597588 | H6: 310.06132 | I6: =H6/H5-1 -> 0.026907263 | J6: unlevered beta | K6: =K3/(1+(1-K5)*K4) -> 0.69030353 | L6: 65.811213 | M6: =L6/L5-1 -> 0.038372976 | N6: unlevered beta | O6: =O3/(1+(1-O5)*O4) -> 1.081309 | P6: 559.52449 | Q6: =P6/P5-1 -> 0.012310382 | R6: unlevered beta | S6: =S3/(1+(1-S5)*S4) -> 0.7909105
A7: 44204 | B7: 11925.6 | C7: =B7/B6-1 -> 0.013555894 | D7: 345.44248 | E7: =D7/D6-1 -> -0.01091852 | F7: Revenue (₹ Cr.) | G7: 23506 | H7: 324.32495 | I7: =H7/H6-1 -> 0.046002619 | J7: Revenue (₹ Cr.) | K7: 27380 | L7: 68.82695 | M7: =L7/L6-1 -> 0.045824065 | N7: Revenue (₹ Cr.) | O7: 5609 | P7: 584.15128 | Q7: =P7/P6-1 -> 0.044013793 | R7: Revenue (₹ Cr.) | S7: 4487
A8: 44207 | B8: 12006.5 | C8: =B8/B7-1 -> 0.0067837587 | D8: 347.77814 | E8: =D8/D7-1 -> 0.0067613631 | F8: % Revenue of Total | G8: =G7/(SUM($G$7,$K$7,$O$7,$S$7)) -> 0.385458 | H8: 314.67739 | I8: =H8/H7-1 -> -0.029746599 | J8: % Revenue of Total | K8: =K7/(SUM($G$7,$K$7,$O$7,$S$7)) -> 0.44898495 | L8: 67.027237 | M8: =L8/L7-1 -> -0.026148379 | N8: % Revenue of Total | O8: =O7/(SUM($G$7,$K$7,$O$7,$S$7)) -> 0.091977961 | P8: 618.65518 | Q8: =P8/P7-1 -> 0.059066718 | R8: % Revenue of Total | S8: =S7/(SUM($G$7,$K$7,$O$7,$S$7)) -> 0.073579089
A9: 44208 | B9: 12058.35 | C9: =B9/B8-1 -> 0.0043184616 | D9: 348.15949 | E9: =D9/D8-1 -> 0.0010965461 | H9: 311.90775 | I9: =H9/H8-1 -> -0.0088015253 | L9: 65.37344 | M9: =L9/L8-1 -> -0.024673509 | P9: 625.67887 | Q9: =P9/P8-1 -> 0.011353154
A10: 44209 | B10: 12041.1 | C10: =B10/B9-1 -> -0.001430544 | D10: 334.43139 | E10: =D10/D9-1 -> -0.039430503 | H10: 305.30677 | I10: =H10/H9-1 -> -0.021163237 | L10: 64.10878 | M10: =L10/L9-1 -> -0.019345167 | P10: 718.39153 | Q10: =P10/P9-1 -> 0.1481793
A11: 44210 | B11: 12069.5 | C11: =B11/B10-1 -> 0.002358621 | D11: 344.20312 | E11: =D11/D10-1 -> 0.029218929 | H11: 308.58417 | I11: =H11/H10-1 -> 0.010734774 | L11: 67.173161 | M11: =L11/L10-1 -> 0.047799713 | P11: 673.65941 | Q11: =P11/P10-1 -> -0.062267046
A12: 44211 | B12: 11931.2 | C12: =B12/B11-1 -> -0.011458619 | D12: 336.81474 | E12: =D12/D11-1 -> -0.021465172 | H12: 308.26104 | I12: =H12/H11-1 -> -0.0010471503 | L12: 65.713932 | M12: =L12/L11-1 -> -0.021723395 | P12: 651.40312 | Q12: =P12/P11-1 -> -0.0330379
A13: 44214 | B13: 11776.2 | C13: =B13/B12-1 -> -0.012991149 | D13: 329.66469 | E13: =D13/D12-1 -> -0.021228418 | H13: 297.41328 | I13: =H13/H12-1 -> -0.035190178 | L13: 64.449265 | M13: =L13/L12-1 -> -0.019245038 | P13: 629.32238 | Q13: =P13/P12-1 -> -0.033897189
A14: 44215 | B14: 11981.85 | C14: =B14/B13-1 -> 0.017463138 | D14: 332.04804 | E14: =D14/D13-1 -> 0.0072296127 | H14: 298.29035 | I14: =H14/H13-1 -> 0.002948999 | L14: 67.270442 | M14: =L14/L13-1 -> 0.043773614 | P14: 659.04138 | Q14: =P14/P13-1 -> 0.047223814
A15: 44216 | B15: 12078.35 | C15: =B15/B14-1 -> 0.0080538484 | D15: 336.71942 | E15: =D15/D14-1 -> 0.01406839 | H15: 295.93613 | I15: =H15/H14-1 -> -0.007892355 | L15: 66.686751 | M15: =L15/L14-1 -> -0.0086767834 | P15: 646.53044 | Q15: =P15/P14-1 -> -0.018983546
A16: 44217 | B16: 12015.95 | C16: =B16/B15-1 -> -0.0051662202 | D16: 338.10175 | E16: =D16/D15-1 -> 0.004105266 | H16: 297.64408 | I16: =H16/H15-1 -> 0.0057713307 | L16: 63.671007 | M16: =L16/L15-1 -> -0.04522254 | P16: 672.2108 | Q16: =P16/P15-1 -> 0.039720259
A17: 44218 | B17: 11854.5 | C17: =B17/B16-1 -> -0.013436324 | D17: 340.77111 | E17: =D17/D16-1 -> 0.0078951645 | H17: 289.98142 | I17: =H17/H16-1 -> -0.025744356 | L17: 62.260421 | M17: =L17/L16-1 -> -0.022154277 | P17: 667.64539 | Q17: =P17/P16-1 -> -0.0067916273
A18: 44221 | B18: 11743.7 | C18: =B18/B17-1 -> -0.0093466451 | D18: 341.10476 | E18: =D18/D17-1 -> 0.00097910194 | H18: 292.88954 | I18: =H18/H17-1 -> 0.010028621 | L18: 59.293324 | M18: =L18/L17-1 -> -0.047656235 | P18: 653.33464 | Q18: =P18/P17-1 -> -0.021434664
A19: 44223 | B19: 11546.35 | C19: =B19/B18-1 -> -0.016804805 | D19: 342.01045 | E19: =D19/D18-1 -> 0.0026551426 | H19: 293.02801 | I19: =H19/H18-1 -> 0.00047278172 | L19: 60.314783 | M19: =L19/L18-1 -> 0.017227219 | P19: 641.17485 | Q19: =P19/P18-1 -> -0.018611878
A20: 44224 | B20: 11442.55 | C20: =B20/B19-1 -> -0.0089898373 | D20: 341.15245 | E20: =D20/D19-1 -> -0.0025086829 | H20: 290.99696 | I20: =H20/H19-1 -> -0.0069312542 | L20: 60.022938 | M20: =L20/L19-1 -> -0.0048386982 | P20: 634.28288 | Q20: =P20/P19-1 -> -0.01074898
... A1435: 46309 | B1435: 22038 | C1435: =B1435/B1434-1 -> -0.0023540063 | D1435: 360.25 | E1435: =D1435/D1434-1 -> 0.0016682886 | H1435: 1400.1 | I1435: =H1435/H1434-1 -> -0.012275132 | L1435: 529.35 | M1435: =L1435/L1434-1 -> 0.0021772056 | P1435: 305.4 | Q1435: =P1435/P1434-1 -> 0.007754496
